Workbook

Sheet Tổng quan
A1: NỀN TẢNG PHIM NGẮN AI — TÀI LIỆU YÊU CẦU & KẾ HOẠCH 8 SPRINT
A2: Bản nháp phục vụ họp khách hàng · Ước lượng sơ bộ (±30%) · Cần tinh chỉnh sau buổi discovery
B4: 1. MỤC TIÊU DỰ ÁN
B5: Xây website cho phép: (1) xưởng phim tạo phim AI ngắn/dài (2–30 phút, có thể tới 60 phút) qua một quy trình khép kín; (2) khách xem short quảng bá trên TikTok/Facebook, bấm vào website và mua lẻ phim hoặc đăng ký gói; (3) đầy đủ Admin, phân quyền vai trò, thanh toán, analytics.
B7: 2. PHẠM VI & GIẢ ĐỊNH (cần khách xác nhận)
B8: • Phim AI được tạo bằng API bên thứ ba (Veo/Kling/Runway/Luma/... + LLM + TTS) qua lớp adapter — KHÔNG tự huấn luyện model.
B9: • Người tạo phim là đội Creator/studio nội bộ của khách. Cho khách cuối tự tạo phim (UGC) nằm ở Backlog (FR-AIV-21).
B10: • Nền tảng web responsive (mobile-first), chưa có app native. Ngôn ngữ giao diện: tiếng Việt.
B11: • Thanh toán nội địa (VNPay/MoMo/PayOS/VietQR) trong 8 tuần; Stripe và thẻ quốc tế ở Backlog. Thủ tục đăng ký merchant do khách chuẩn bị sớm.
B12: • Đăng tự động lên TikTok/Facebook cần app review của nền tảng → Backlog; trong phạm vi chỉ có landing page + tracking + Pixel/CAPI.
B13: • Phim dài được ghép từ nhiều cảnh 5–10 giây; chi phí API AI và hạ tầng KHÔNG nằm trong estimate man-day.
B14: • 'Ưu tiên' theo MoSCoW. Chức năng Should/Could chưa xếp sprint được đặt ở Backlog (Phase 2) vì năng lực 3 dev chỉ đủ MVP.
B15: • Sprint = 1 tuần (T2–T6). Chưa gán người; sprint nào vượt năng lực sẽ được cảnh báo ở sheet 'Sprint'.
B17: 3. ĐỘI NGŨ & THAM SỐ KẾ HOẠCH (ô vàng = có thể sửa)
B18: Ngày bắt đầu Sprint 1 | C18: 46300 | D18: Thứ Hai; sửa để tự dời toàn bộ lịch
B19: Ngày làm việc / sprint | C19: 5
B20: Số dev (Backend, Frontend, AI) | C20: 3 | D20: Dùng chung 1 pool nên FE/BE/AI có thể hỗ trợ nhau
B21: Hệ số hiệu dụng của dev | C21: 0.9 | D21: Trừ họp, review, gián đoạn
B22: Số lead (BA + Tester + Team Lead) | C22: 1
B23: Hệ số hiệu dụng của lead cho BA+QA | C23: 0.85 | D23: Phần còn lại dành cho quản lý team/làm việc với khách
B24: Đơn giá / man-day (VND) | D24: Nhập để tính chi phí ở sheet 'Effort'; để trống thì không tính
B25: Năng lực dev / sprint (man-day) | C25: =C20*C19*C21 -> 13.5
B26: Năng lực lead / sprint (man-day) | C26: =C22*C19*C23 -> 4.25
B28: 4. SỐ LIỆU CHÍNH (tự tính từ sheet FR)
B29: Tổng số FR | C29: =COUNTA(FR!$A$4:$A$500) -> 95
B30: FR trong 8 sprint (MVP) | C30: =COUNTIFS(FR!$G$4:$G$500,"<>Backlog",FR!$A$4:$A$500,"<>") -> 53
B31: FR ở Backlog (Phase 2) | C31: =COUNTIF(FR!$G$4:$G$500,"Backlog") -> 42
B32: Tổng số Use Case | C32: =COUNTA(UC!$A$4:$A$200) -> 22
B33: Man-day trong 8 sprint (tất cả vai trò) | C33: =SUMIFS(FR!$M$4:$M$500,FR!$G$4:$G$500,"<>Backlog",FR!$A$4:$A$500,"<>") -> 138.95
B34: Man-day của Backlog (Phase 2) | C34: =SUMIFS(FR!$M$4:$M$500,FR!$G$4:$G$500,"Backlog") -> 85.9
B35: Tổng năng lực dev 8 sprint | C35: =C25*8 -> 108
B36: Dev đã lập kế hoạch / năng lực | C36: =SUMIFS(FR!$N$4:$N$500,FR!$G$4:$G$500,"<>Backlog",FR!$A$4:$A$500,"<>")/C35 -> 0.93518519
B38: 5. CHÚ GIẢI
B39: Chữ xanh dương / ô vàng: giá trị nhập tay (ước lượng, tham số). Chữ đen: công thức.
B40: MoSCoW: Must = bắt buộc cho MVP · Should = quan trọng, làm nếu còn năng lực · Could = mong muốn, để Phase 2.
B41: Vai trò trong ước lượng: BA (phân tích/tài liệu), BE (backend), FE (frontend), AI (pipeline & tích hợp AI), QA (kiểm thử). Đơn vị: man-day.
B42: Các sheet: Roles · FR · UC · Sprint · Effort · Rủi ro-Câu hỏi.

Sheet Roles
A1: VAI TRÒ & MA TRẬN PHÂN QUYỀN (RBAC)
A2: C = Tạo · R = Xem · U = Sửa · D = Xóa · A = Duyệt/Xuất bản · — = không có quyền
A4: Vai trò | B4: Mô tả | C4: Xem & mua phim | D4: Hồ sơ cá nhân | E4: Catalog (phim/tập/giá) | F4: AI Studio (tạo phim) | G4: Kiểm duyệt | H4: Chiến dịch & Analytics | I4: Đơn hàng & tài chính | J4: Người dùng & phân quyền | K4: Cấu hình hệ thống | L4: Audit log
A5: Guest | B5: Khách chưa đăng nhập, xem landing/trailer | C5: R (preview) | D5: — | E5: R | F5: — | G5: — | H5: — | I5: — | J5: — | K5: — | L5: —
A6: User | B6: Đã đăng ký, mua lẻ | C6: R + mua | D6: CRUD (của mình) | E6: R | F6: — | G6: — | H6: — | I6: R (của mình) | J6: — | K6: — | L6: —
A7: Subscriber | B7: User có gói còn hạn | C7: R (theo gói) | D7: CRUD (của mình) | E7: R | F7: — | G7: — | H7: — | I7: R (của mình) | J7: — | K7: — | L7: —
A8: Creator / Editor | B8: Tạo phim AI | C8: R | D8: CRUD (của mình) | E8: R | F8: CRUD (dự án của mình) | G8: — | H8: — | I8: — | J8: — | K8: — | L8: —
A9: Content Manager | B9: Quản lý catalog, duyệt xuất bản | C9: R | D9: CRUD (của mình) | E9: CRUD + A | F9: R + A | G9: — | H9: R | I9: — | J9: — | K9: — | L9: —
A10: Moderator | B10: Kiểm duyệt nội dung AI/UGC | C10: R | D10: CRUD (của mình) | E10: R | F10: R | G10: R + A | H10: — | I10: — | J10: — | K10: — | L10: R
A11: Marketing | B11: Chiến dịch, tracking, báo cáo | C11: R | D11: CRUD (của mình) | E11: R | F11: — | G11: — | H11: CRUD | I11: R | J11: — | K11: — | L11: —
A12: Finance | B12: Đối soát, hoàn tiền | C12: R | D12: CRUD (của mình) | E12: R | F12: — | G12: — | H12: R | I12: R + hoàn tiền | J12: — | K12: — | L12: R
A13: Support | B13: Hỗ trợ khách | C13: R | D13: CRUD (của mình) | E13: R | F13: — | G13: — | H13: — | I13: R | J13: R (giới hạn) | K13: — | L13: —
A14: Admin | B14: Quản trị vận hành | C14: R | D14: CRUD | E14: CRUD + A | F14: CRUD | G14: A | H14: CRUD | I14: CRUD | J14: CRUD (trừ Super Admin) | K14: U | L14: R
A15: Super Admin | B15: Toàn quyền, quản lý vai trò | C15: R | D15: CRUD | E15: CRUD + A | F15: CRUD | G15: A | H15: CRUD | I15: CRUD | J15: CRUD | K15: CRUD | L15: R

Sheet FR
A1: DANH SÁCH YÊU CẦU CHỨC NĂNG (FR) & ƯỚC LƯỢNG MAN-DAY
A2: TỔNG (theo bộ lọc) | H2: =SUBTOTAL(109,H4:H500) -> 32 | I2: =SUBTOTAL(109,I4:I500) -> 74.35 | J2: =SUBTOTAL(109,J4:J500) -> 66.75 | K2: =SUBTOTAL(109,K4:K500) -> 23.75 | L2: =SUBTOTAL(109,L4:L500) -> 28 | M2: =SUBTOTAL(109,M4:M500) -> 224.85 | N2: =SUBTOTAL(109,N4:N500) -> 164.85
A3: ID | B3: Module | C3: Tên chức năng | D3: Mô tả | E3: Actor | F3: Ưu tiên | G3: Sprint | H3: BA | I3: BE | J3: FE | K3: AI | L3: QA | M3: Tổng (md) | N3: Dev (BE+FE+AI) | O3: UC liên quan | P3: Trạng thái | Q3: Ghi chú
A4: FR-SYS-01 | B4: SYS · Nền tảng & hạ tầng | C4: Khởi tạo repo, môi trường & CI/CD | D4: Monorepo/2 repo, Docker, môi trường dev/staging/prod, pipeline build-test-deploy tự động. | E4: Dev team | F4: Must | G4: S1 | H4: 0 | I4: 1.5 | J4: 0.5 | K4: 0.5 | L4: 0.2 | M4: =SUM(H4:L4) -> 2.7 | N4: =SUM(I4:K4) -> 2.5 | O4: — | P4: Đề xuất
A5: FR-SYS-02 | B5: SYS · Nền tảng & hạ tầng | C5: Thiết kế CSDL & migration | D5: ERD lõi: user, role, film, episode, order, subscription, entitlement, ai_project, ai_job, asset... | E5: Dev team | F5: Must | G5: S1 | H5: 0.5 | I5: 1.5 | J5: 0 | K5: 0 | L5: 0.2 | M5: =SUM(H5:L5) -> 2.2 | N5: =SUM(I5:K5) -> 1.5 | O5: — | P5: Đề xuất
A6: FR-SYS-03 | B6: SYS · Nền tảng & hạ tầng | C6: Design system & UI kit responsive | D6: Theme tối, component dùng chung, layout mobile-first (khách vào từ TikTok/FB chủ yếu trên điện thoại). | E6: Dev team | F6: Must | G6: S1 | H6: 0.5 | I6: 0 | J6: 2 | K6: 0 | L6: 0.2 | M6: =SUM(H6:L6) -> 2.7 | N6: =SUM(I6:K6) -> 2 | O6: — | P6: Đề xuất
A7: FR-SYS-04 | B7: SYS · Nền tảng & hạ tầng | C7: Trang pháp lý & phân loại độ tuổi | D7: Điều khoản, chính sách bảo mật, hoàn tiền, DMCA, cookie consent, cảnh báo/nhãn độ tuổi. | E7: Khách | F7: Must | G7: S4 | H7: 0.75 | I7: 0.25 | J7: 0.5 | K7: 0 | L7: 0.2 | M7: =SUM(H7:L7) -> 1.7 | N7: =SUM(I7:K7) -> 0.75 | O7: — | P7: Đề xuất
A8: FR-SYS-05 | B8: SYS · Nền tảng & hạ tầng | C8: Giám sát, log & cảnh báo | D8: Log tập trung, error tracking, uptime, alert khi job AI/thanh toán lỗi. | E8: Admin | F8: Should | G8: Backlog | H8: 0 | I8: 0.75 | J8: 0.25 | K8: 0.25 | L8: 0.2 | M8: =SUM(H8:L8) -> 1.45 | N8: =SUM(I8:K8) -> 1.25 | O8: — | P8: Đề xuất | Q8: Phase 2 — ngoài 8 sprint
A9: FR-SYS-06 | B9: SYS · Nền tảng & hạ tầng | C9: SEO & hiệu năng web | D9: Meta/OG, sitemap, lazy-load, Lighthouse cho trang phim/landing. | E9: Khách | F9: Should | G9: Backlog | H9: 0.25 | I9: 0.25 | J9: 1 | K9: 0 | L9: 0.2 | M9: =SUM(H9:L9) -> 1.7 | N9: =SUM(I9:K9) -> 1.25 | O9: — | P9: Đề xuất | Q9: Phase 2 — ngoài 8 sprint
A10: FR-SYS-07 | B10: SYS · Nền tảng & hạ tầng | C10: Bảo mật & backup | D10: OWASP Top 10, rate-limit, CORS/CSRF, mã hóa dữ liệu nhạy cảm, backup DB & storage định kỳ. | E10: Dev team | F10: Must | G10: S8 | H10: 0 | I10: 1.5 | J10: 0.25 | K10: 0 | L10: 0.6 | M10: =SUM(H10:L10) -> 2.35 | N10: =SUM(I10:K10) -> 1.75 | O10: — | P10: Đề xuất
A11: FR-SYS-08 | B11: SYS · Nền tảng & hạ tầng | C11: Kiểm thử hiệu năng | D11: Load test streaming, checkout, hàng đợi job AI. | E11: Dev team | F11: Must | G11: S8 | H11: 0 | I11: 0.5 | J11: 0.25 | K11: 0 | L11: 0.8 | M11: =SUM(H11:L11) -> 1.55 | N11: =SUM(I11:K11) -> 0.75 | O11: — | P11: Đề xuất
A12: FR-SYS-09 | B12: SYS · Nền tảng & hạ tầng | C12: UAT cùng khách & sửa lỗi | D12: Phiên UAT, ghi nhận & sửa lỗi, chốt nghiệm thu. | E12: BA/Khách | F12: Must | G12: S8 | H12: 1.5 | I12: 1.5 | J12: 1.5 | K12: 0.5 | L12: 1.6 | M12: =SUM(H12:L12) -> 6.6 | N12: =SUM(I12:K12) -> 3.5 | O12: — | P12: Đề xuất
A13: FR-SYS-10 | B13: SYS · Nền tảng & hạ tầng | C13: Tài liệu & bàn giao vận hành | D13: Tài liệu người dùng/admin/kỹ thuật, hướng dẫn deploy, đào tạo. | E13: BA | F13: Must | G13: S8 | H13: 2 | I13: 0.25 | J13: 0.25 | K13: 0.25 | L13: 0.2 | M13: =SUM(H13:L13) -> 2.95 | N13: =SUM(I13:K13) -> 0.75 | O13: — | P13: Đề xuất
A14: FR-SYS-11 | B14: SYS · Nền tảng & hạ tầng | C14: Đa ngôn ngữ giao diện (vi/en) | D14: i18n toàn bộ giao diện. | E14: Khách | F14: Could | G14: Backlog | H14: 0.25 | I14: 0.25 | J14: 1.5 | K14: 0 | L14: 0.4 | M14: =SUM(H14:L14) -> 2.4 | N14: =SUM(I14:K14) -> 1.75 | O14: — | P14: Đề xuất | Q14: Phase 2 — ngoài 8 sprint
A15: FR-AUTH-01 | B15: AUTH · Tài khoản & xác thực | C15: Đăng ký tài khoản | D15: Đăng ký email + mật khẩu, xác thực email, điều khoản. | E15: Guest | F15: Must | G15: S1 | H15: 0.25 | I15: 0.75 | J15: 0.5 | K15: 0 | L15: 0.2 | M15: =SUM(H15:L15) -> 1.7 | N15: =SUM(I15:K15) -> 1.25 | O15: UC-02 | P15: Đề xuất
A16: FR-AUTH-02 | B16: AUTH · Tài khoản & xác thực | C16: Đăng nhập / đăng xuất | D16: JWT access + refresh token, ghi nhớ đăng nhập, khóa tạm khi sai nhiều lần. | E16: Guest/User | F16: Must | G16: S1 | H16: 0.25 | I16: 0.75 | J16: 0.5 | K16: 0 | L16: 0.2 | M16: =SUM(H16:L16) -> 1.7 | N16: =SUM(I16:K16) -> 1.25 | O16: UC-03 | P16: Đề xuất
A17: FR-AUTH-03 | B17: AUTH · Tài khoản & xác thực | C17: Quên / đặt lại mật khẩu | D17: Gửi link đặt lại có hạn dùng qua email. | E17: User | F17: Must | G17: S2 | H17: 0.25 | I17: 0.5 | J17: 0.25 | K17: 0 | L17: 0.2 | M17: =SUM(H17:L17) -> 1.2 | N17: =SUM(I17:K17) -> 0.75 | O17: UC-03 | P17: Đề xuất
A18: FR-AUTH-04 | B18: AUTH · Tài khoản & xác thực | C18: Đăng nhập Google / Facebook | D18: OAuth social login, liên kết với tài khoản email sẵn có. | E18: Guest | F18: Should | G18: Backlog | H18: 0.25 | I18: 0.75 | J18: 0.25 | K18: 0 | L18: 0.2 | M18: =SUM(H18:L18) -> 1.45 | N18: =SUM(I18:K18) -> 1 | O18: — | P18: Đề xuất | Q18: Phase 2 — ngoài 8 sprint
A19: FR-AUTH-05 | B19: AUTH · Tài khoản & xác thực | C19: Hồ sơ cá nhân | D19: Cập nhật tên, avatar, đổi mật khẩu, xóa tài khoản. | E19: User | F19: Should | G19: Backlog | H19: 0.25 | I19: 0.25 | J19: 0.75 | K19: 0 | L19: 0.2 | M19: =SUM(H19:L19) -> 1.45 | N19: =SUM(I19:K19) -> 1 | O19: — | P19: Đề xuất | Q19: Phase 2 — ngoài 8 sprint
A20: FR-AUTH-06 | B20: AUTH · Tài khoản & xác thực | C20: Giới hạn thiết bị & phiên đăng nhập | D20: Giới hạn số thiết bị xem đồng thời, chống share tài khoản. | E20: Subscriber | F20: Could | G20: Backlog | H20: 0.25 | I20: 1 | J20: 0.5 | K20: 0 | L20: 0.4 | M20: =SUM(H20:L20) -> 2.15 | N20: =SUM(I20:K20) -> 1.5 | O20: — | P20: Đề xuất | Q20: Phase 2 — ngoài 8 sprint
A21: FR-AUTH-07 | B21: AUTH · Tài khoản & xác thực | C21: Đăng nhập OTP SĐT / Zalo | D21: Xác thực bằng số điện thoại. | E21: Guest | F21: Could | G21: Backlog | H21: 0.25 | I21: 1 | J21: 0.5 | K21: 0 | L21: 0.4 | M21: =SUM(H21:L21) -> 2.15 | N21: =SUM(I21:K21) -> 1.5 | O21: — | P21: Đề xuất | Q21: Phase 2 — ngoài 8 sprint
A22: FR-ADM-01 | B22: ADM · Admin & phân quyền | C22: Mô hình vai trò & quyền (RBAC) | D22: Vai trò: Super Admin, Admin, Content Manager, Creator, Moderator, Marketing, Finance, Support, User. Guard ở API & UI. | E22: Admin | F22: Must | G22: S1 | H22: 1 | I22: 1.5 | J22: 0.25 | K22: 0 | L22: 0.4 | M22: =SUM(H22:L22) -> 3.15 | N22: =SUM(I22:K22) -> 1.75 | O22: UC-20 | P22: Đề xuất
A23: FR-ADM-02 | B23: ADM · Admin & phân quyền | C23: Quản lý người dùng | D23: Danh sách/tìm kiếm, khóa/mở khóa, đổi vai trò, xem lịch sử mua. | E23: Admin | F23: Must | G23: S2 | H23: 0.25 | I23: 0.5 | J23: 1 | K23: 0 | L23: 0.2 | M23: =SUM(H23:L23) -> 1.95 | N23: =SUM(I23:K23) -> 1.5 | O23: UC-20 | P23: Đề xuất
A24: FR-ADM-03 | B24: ADM · Admin & phân quyền | C24: Ma trận phân quyền động | D24: Giao diện tạo vai trò tùy chỉnh và gán permission theo chức năng. | E24: Super Admin | F24: Should | G24: Backlog | H24: 0.25 | I24: 0.75 | J24: 0.75 | K24: 0 | L24: 0.2 | M24: =SUM(H24:L24) -> 1.95 | N24: =SUM(I24:K24) -> 1.5 | O24: — | P24: Đề xuất | Q24: Phase 2 — ngoài 8 sprint
A25: FR-ADM-04 | B25: ADM · Admin & phân quyền | C25: Audit log | D25: Ghi lại hành động nhạy cảm (đổi giá, xuất bản, hoàn tiền, đổi quyền); lọc & xem. | E25: Admin | F25: Should | G25: S8 | H25: 0.25 | I25: 0.75 | J25: 0.5 | K25: 0 | L25: 0.2 | M25: =SUM(H25:L25) -> 1.7 | N25: =SUM(I25:K25) -> 1.25 | O25: UC-15, UC-20 | P25: Đề xuất
A26: FR-ADM-05 | B26: ADM · Admin & phân quyền | C26: Dashboard tổng quan | D26: Doanh thu, user mới, lượt xem, tỉ lệ chuyển đổi, job AI đang chạy. | E26: Admin | F26: Must | G26: S7 | H26: 0.5 | I26: 1 | J26: 1.5 | K26: 0 | L26: 0.4 | M26: =SUM(H26:L26) -> 3.4 | N26: =SUM(I26:K26) -> 2.5 | O26: UC-19, UC-21 | P26: Đề xuất
A27: FR-ADM-06 | B27: ADM · Admin & phân quyền | C27: Cấu hình hệ thống | D27: Giá credit, banner, provider AI, SMTP, cấu hình thanh toán. | E27: Admin | F27: Should | G27: Backlog | H27: 0.25 | I27: 0.75 | J27: 0.75 | K27: 0 | L27: 0.2 | M27: =SUM(H27:L27) -> 1.95 | N27: =SUM(I27:K27) -> 1.5 | O27: — | P27: Đề xuất | Q27: Phase 2 — ngoài 8 sprint
A28: FR-ADM-07 | B28: ADM · Admin & phân quyền | C28: Quản lý banner & curation trang chủ | D28: Sắp xếp banner, hàng phim nổi bật, bộ sưu tập theo chiến dịch. | E28: Content Manager | F28: Should | G28: Backlog | H28: 0.25 | I28: 0.5 | J28: 1 | K28: 0 | L28: 0.2 | M28: =SUM(H28:L28) -> 1.95 | N28: =SUM(I28:K28) -> 1.5 | O28: — | P28: Đề xuất | Q28: Phase 2 — ngoài 8 sprint
A29: FR-ADM-08 | B29: ADM · Admin & phân quyền | C29: Quản lý ticket hỗ trợ | D29: Nhận & xử lý khiếu nại, yêu cầu hoàn tiền. | E29: Support | F29: Could | G29: Backlog | H29: 0.5 | I29: 1 | J29: 1 | K29: 0 | L29: 0.4 | M29: =SUM(H29:L29) -> 2.9 | N29: =SUM(I29:K29) -> 2 | O29: — | P29: Đề xuất | Q29: Phase 2 — ngoài 8 sprint
A30: FR-CAT-01 | B30: CAT · Quản lý danh mục phim | C30: Quản lý phim / series | D30: CRUD phim: tên, mô tả, poster, trailer, thể loại, tag, thời lượng, độ tuổi. | E30: Content Manager | F30: Must | G30: S2 | H30: 0.75 | I30: 1 | J30: 1.5 | K30: 0 | L30: 0.4 | M30: =SUM(H30:L30) -> 3.65 | N30: =SUM(I30:K30) -> 2.5 | O30: UC-16, UC-17 | P30: Đề xuất
A31: FR-CAT-02 | B31: CAT · Quản lý danh mục phim | C31: Quản lý mùa / tập | D31: Quản lý season, tập, thứ tự, video gắn với tập. | E31: Content Manager | F31: Must | G31: S2 | H31: 0.25 | I31: 0.75 | J31: 0.75 | K31: 0 | L31: 0.2 | M31: =SUM(H31:L31) -> 1.95 | N31: =SUM(I31:K31) -> 1.5 | O31: UC-17 | P31: Đề xuất
A32: FR-CAT-03 | B32: CAT · Quản lý danh mục phim | C32: Thể loại, tag, bộ sưu tập | D32: Danh mục thể loại và bộ sưu tập do admin tạo. | E32: Content Manager | F32: Should | G32: Backlog | H32: 0.25 | I32: 0.25 | J32: 0.75 | K32: 0 | L32: 0.2 | M32: =SUM(H32:L32) -> 1.45 | N32: =SUM(I32:K32) -> 1 | O32: — | P32: Đề xuất | Q32: Phase 2 — ngoài 8 sprint
A33: FR-CAT-04 | B33: CAT · Quản lý danh mục phim | C33: Vòng đời xuất bản | D33: Draft → Scheduled → Published → Archived; lên lịch phát hành. | E33: Content Manager | F33: Must | G33: S3 | H33: 0.25 | I33: 0.75 | J33: 0.5 | K33: 0 | L33: 0.2 | M33: =SUM(H33:L33) -> 1.7 | N33: =SUM(I33:K33) -> 1.25 | O33: UC-16 | P33: Đề xuất
A34: FR-CAT-05 | B34: CAT · Quản lý danh mục phim | C34: Định giá & mô hình bán | D34: Miễn phí / mua lẻ phim hoặc tập / chỉ dành cho gói; giá khuyến mãi. | E34: Content Manager | F34: Must | G34: S3 | H34: 0.5 | I34: 0.75 | J34: 0.75 | K34: 0 | L34: 0.4 | M34: =SUM(H34:L34) -> 2.4 | N34: =SUM(I34:K34) -> 1.5 | O34: UC-16, UC-17 | P34: Đề xuất
A35: FR-CAT-06 | B35: CAT · Quản lý danh mục phim | C35: Phụ đề & lồng tiếng đa ngôn ngữ | D35: Nhiều track phụ đề/âm thanh cho một phim. | E35: Content Manager | F35: Could | G35: Backlog | H35: 0.25 | I35: 0.75 | J35: 0.75 | K35: 0 | L35: 0.2 | M35: =SUM(H35:L35) -> 1.95 | N35: =SUM(I35:K35) -> 1.5 | O35: — | P35: Đề xuất | Q35: Phase 2 — ngoài 8 sprint
A36: FR-CAT-07 | B36: CAT · Quản lý danh mục phim | C36: Đánh giá & bình luận | D36: Rating, bình luận, báo cáo vi phạm. | E36: User | F36: Could | G36: Backlog | H36: 0.5 | I36: 1 | J36: 1 | K36: 0 | L36: 0.4 | M36: =SUM(H36:L36) -> 2.9 | N36: =SUM(I36:K36) -> 2 | O36: — | P36: Đề xuất | Q36: Phase 2 — ngoài 8 sprint
A37: FR-MED-01 | B37: MED · Media & streaming | C37: Upload video lớn (resumable) | D37: Upload chunk/resume lên object storage, hiển thị tiến trình. | E37: Content Manager | F37: Must | G37: S2 | H37: 0.25 | I37: 1.5 | J37: 0.75 | K37: 0 | L37: 0.2 | M37: =SUM(H37:L37) -> 2.7 | N37: =SUM(I37:K37) -> 2.25 | O37: UC-17 | P37: Đề xuất
A38: FR-MED-02 | B38: MED · Media & streaming | C38: Transcode HLS đa bitrate | D38: Worker FFmpeg tạo HLS 360p–1080p, thumbnail, sprite preview. | E38: Hệ thống | F38: Must | G38: S2 | H38: 0.25 | I38: 2 | J38: 0 | K38: 0 | L38: 0.4 | M38: =SUM(H38:L38) -> 2.65 | N38: =SUM(I38:K38) -> 2 | O38: UC-17 | P38: Đề xuất
A39: FR-MED-03 | B39: MED · Media & streaming | C39: Bảo vệ nội dung (signed URL) | D39: Signed URL/token hết hạn, chống hotlink, watermark người xem (tùy chọn). | E39: Hệ thống | F39: Must | G39: S4 | H39: 0.25 | I39: 1.5 | J39: 0.25 | K39: 0 | L39: 0.4 | M39: =SUM(H39:L39) -> 2.4 | N39: =SUM(I39:K39) -> 1.75 | O39: UC-07 | P39: Đề xuất
A40: FR-MED-04 | B40: MED · Media & streaming | C40: Cấu hình CDN & cache | D40: CDN cho HLS segment và ảnh, chính sách cache. | E40: Dev team | F40: Should | G40: Backlog | H40: 0.25 | I40: 0.75 | J40: 0 | K40: 0 | L40: 0.2 | M40: =SUM(H40:L40) -> 1.2 | N40: =SUM(I40:K40) -> 0.75 | O40: — | P40: Đề xuất | Q40: Phase 2 — ngoài 8 sprint
...

Sheet UC
A1: DANH SÁCH USE CASE (UC)
A2: Sprint lấy tự động từ FR chính. UC ở Backlog nghĩa là chức năng tương ứng thuộc Phase 2.
A3: ID | B3: Tên Use Case | C3: Actor | D3: FR chính | E3: FR liên quan | F3: Điều kiện tiên quyết | G3: Luồng chính | H3: Luồng thay thế / ngoại lệ | I3: Hậu điều kiện | J3: Ưu tiên | K3: Sprint
A4: UC-01 | B4: Từ short TikTok/FB vào trang phim | C4: Guest | D4: FR-SOC-01 | E4: FR-SOC-02, FR-PLY-02, FR-ANA-01 | F4: Short có link/nút CTA trỏ tới landing của phim. | G4: 1. Khách xem short trên TikTok/Facebook. 2. Bấm link trong bio/mô tả/CTA. 3. Hệ thống mở landing theo chiến dịch và lưu UTM/click-id. 4. Khách thấy trailer, giá và nút Xem/Mua. | H4: A1. Phim đã gỡ/hết hạn → chuyển về trang chủ kèm gợi ý. A2. Trình duyệt in-app của TikTok/FB chặn tính năng → hiển thị hướng dẫn mở bằng trình duyệt ngoài. | I4: Truy cập được ghi nhận kèm nguồn; khách ở trang chi tiết phim. | J4: =INDEX(FR!$F$4:$F$500,MATCH(D4,FR!$A$4:$A$500,0)) -> Must | K4: =INDEX(FR!$G$4:$G$500,MATCH(D4,FR!$A$4:$A$500,0)) -> S3
A5: UC-02 | B5: Đăng ký tài khoản | C5: Guest | D5: FR-AUTH-01 | E5: FR-NOT-01 | F5: Chưa có tài khoản. | G5: 1. Nhập email, mật khẩu, đồng ý điều khoản. 2. Hệ thống tạo tài khoản, gửi email xác thực. 3. Khách xác thực và được đăng nhập. | H5: A1. Email đã tồn tại → báo lỗi, gợi ý đăng nhập/quên mật khẩu. A2. Chưa xác thực email → hạn chế mua hàng. | I5: Tài khoản User được tạo; nguồn truy cập được gắn vào user. | J5: =INDEX(FR!$F$4:$F$500,MATCH(D5,FR!$A$4:$A$500,0)) -> Must | K5: =INDEX(FR!$G$4:$G$500,MATCH(D5,FR!$A$4:$A$500,0)) -> S1
A6: UC-03 | B6: Đăng nhập / quên mật khẩu | C6: User | D6: FR-AUTH-02 | E6: FR-AUTH-03 | F6: Đã có tài khoản. | G6: 1. Nhập email + mật khẩu. 2. Hệ thống cấp access/refresh token. 3. Chuyển về trang trước đó. | H6: A1. Sai mật khẩu nhiều lần → khóa tạm. A2. Quên mật khẩu → gửi link đặt lại. | I6: Phiên đăng nhập hợp lệ. | J6: =INDEX(FR!$F$4:$F$500,MATCH(D6,FR!$A$4:$A$500,0)) -> Must | K6: =INDEX(FR!$G$4:$G$500,MATCH(D6,FR!$A$4:$A$500,0)) -> S1
A7: UC-04 | B7: Duyệt và tìm phim | C7: User | D7: FR-PLY-01 | E7: FR-PLY-07, FR-PLY-02 | F7: Có phim ở trạng thái Published. | G7: 1. Mở trang chủ, duyệt các hàng phim. 2. Tìm kiếm/lọc theo thể loại. 3. Mở trang chi tiết. | H7: A1. Không có kết quả → gợi ý phim khác. | I7: Người dùng tới trang chi tiết phim. | J7: =INDEX(FR!$F$4:$F$500,MATCH(D7,FR!$A$4:$A$500,0)) -> Must | K7: =INDEX(FR!$G$4:$G$500,MATCH(D7,FR!$A$4:$A$500,0)) -> S3
A8: UC-05 | B8: Mua lẻ một phim / tập | C8: User | D8: FR-PAY-01 | E8: FR-PAY-02, FR-PAY-03, FR-PAY-04, FR-NOT-01 | F8: Đã đăng nhập; phim có giá. | G8: 1. Bấm Mua ở trang chi tiết. 2. Xem đơn, chọn cổng thanh toán. 3. Thanh toán; cổng gọi webhook. 4. Hệ thống xác nhận đơn, cấp entitlement, gửi email. | H8: A1. Thanh toán thất bại/hủy → đơn ở trạng thái Failed, cho thử lại. A2. Webhook đến trễ/trùng → xử lý idempotent, không cấp quyền hai lần. | I8: Đơn Paid; người dùng có quyền xem phim. | J8: =INDEX(FR!$F$4:$F$500,MATCH(D8,FR!$A$4:$A$500,0)) -> Must | K8: =INDEX(FR!$G$4:$G$500,MATCH(D8,FR!$A$4:$A$500,0)) -> S4
A9: UC-06 | B9: Đăng ký gói thuê bao | C9: User | D9: FR-PAY-05 | E9: FR-PAY-02, FR-PAY-03, FR-PAY-04 | F9: Đã đăng nhập; có gói đang bán. | G9: 1. Chọn gói (tháng/năm). 2. Thanh toán. 3. Hệ thống kích hoạt gói và mở quyền xem theo phạm vi gói. | H9: A1. Gói hết hạn → mất quyền, hiển thị lời mời gia hạn. A2. Hủy gia hạn → giữ quyền đến hết chu kỳ. | I9: Subscription Active với ngày hết hạn. | J9: =INDEX(FR!$F$4:$F$500,MATCH(D9,FR!$A$4:$A$500,0)) -> Must | K9: =INDEX(FR!$G$4:$G$500,MATCH(D9,FR!$A$4:$A$500,0)) -> S7
A10: UC-07 | B10: Xem phim | C10: User | D10: FR-PLY-03 | E10: FR-PLY-05, FR-MED-03 | F10: Có quyền xem (miễn phí / đã mua / gói còn hạn). | G10: 1. Bấm Xem. 2. Hệ thống kiểm tra entitlement, cấp signed URL ngắn hạn. 3. Trình phát HLS chạy, tự chỉnh chất lượng theo mạng. | H10: A1. Chưa có quyền → hiển thị CTA mua/đăng ký. A2. Link hết hạn → cấp lại link. | I10: Lượt xem được ghi nhận. | J10: =INDEX(FR!$F$4:$F$500,MATCH(D10,FR!$A$4:$A$500,0)) -> Must | K10: =INDEX(FR!$G$4:$G$500,MATCH(D10,FR!$A$4:$A$500,0)) -> S3
A11: UC-08 | B11: Xem tiếp phim đang dở | C11: User | D11: FR-PLY-06 | E11: FR-ANA-01, FR-PLY-03 | F11: Đã từng xem một phần. | G11: 1. Mở lại phim. 2. Trình phát tiếp tục từ vị trí đã lưu (nếu có tính năng). | H11: A1. Không có dữ liệu → phát từ đầu. | I11: Vị trí xem cập nhật. | J11: =INDEX(FR!$F$4:$F$500,MATCH(D11,FR!$A$4:$A$500,0)) -> Should | K11: =INDEX(FR!$G$4:$G$500,MATCH(D11,FR!$A$4:$A$500,0)) -> Backlog
A12: UC-09 | B12: Tạo dự án phim AI từ ý tưởng | C12: Creator | D12: FR-AIV-03 | E12: FR-AIV-04, FR-AIV-16 | F12: Có tài khoản Creator; còn hạn mức chi phí. | G12: 1. Tạo dự án, nhập brief (ý tưởng, thể loại, phong cách, thời lượng). 2. Hệ thống ước tính chi phí. 3. Creator xác nhận bắt đầu. | H12: A1. Vượt hạn mức → chặn, yêu cầu Admin cấp thêm. | I12: Dự án ở trạng thái Draft, sẵn sàng tạo kịch bản. | J12: =INDEX(FR!$F$4:$F$500,MATCH(D12,FR!$A$4:$A$500,0)) -> Must | K12: =INDEX(FR!$G$4:$G$500,MATCH(D12,FR!$A$4:$A$500,0)) -> S5
A13: UC-10 | B13: Sinh và chỉnh sửa kịch bản | C13: Creator | D13: FR-AIV-04 | E13: FR-AIV-05, FR-AIV-18 | F13: Có dự án. | G13: 1. Bấm Sinh kịch bản; LLM tạo outline rồi kịch bản. 2. Creator sửa tay hoặc yêu cầu viết lại từng phần. 3. Chốt kịch bản; hệ thống tách cảnh (storyboard). | H13: A1. Prompt vi phạm chính sách → chặn và báo lý do. A2. Provider lỗi → job tự retry, báo trạng thái. | I13: Kịch bản và danh sách cảnh được chốt. | J13: =INDEX(FR!$F$4:$F$500,MATCH(D13,FR!$A$4:$A$500,0)) -> Must | K13: =INDEX(FR!$G$4:$G$500,MATCH(D13,FR!$A$4:$A$500,0)) -> S5
A14: UC-11 | B14: Thiết lập nhân vật và phong cách | C14: Creator | D14: FR-AIV-06 | E14: FR-AIV-07 | F14: Đã có storyboard. | G14: 1. Tạo nhân vật (mô tả/ảnh tham chiếu). 2. Chọn style preset. 3. Sinh thử ảnh, chọn bản ưng ý làm chuẩn cho cả phim. | H14: A1. Kết quả không nhất quán → sinh lại/đổi tham chiếu. | I14: Character sheet và style được khóa cho dự án. | J14: =INDEX(FR!$F$4:$F$500,MATCH(D14,FR!$A$4:$A$500,0)) -> Must | K14: =INDEX(FR!$G$4:$G$500,MATCH(D14,FR!$A$4:$A$500,0)) -> S6
A15: UC-12 | B15: Sinh keyframe và clip cho từng cảnh | C15: Creator | D15: FR-AIV-08 | E15: FR-AIV-07, FR-AIV-15, FR-AIV-14 | F15: Đã có nhân vật và prompt cảnh. | G15: 1. Sinh keyframe, duyệt/chọn. 2. Gửi job sinh clip cho từng cảnh. 3. Theo dõi tiến độ realtime. 4. Xem lại, chấp nhận hoặc tạo lại cảnh. | H15: A1. Job lỗi → retry tự động, sau đó cho Creator thử lại thủ công. A2. Vượt rate-limit provider → xếp hàng chờ. | I15: Mỗi cảnh có một clip được chấp nhận. | J15: =INDEX(FR!$F$4:$F$500,MATCH(D15,FR!$A$4:$A$500,0)) -> Must | K15: =INDEX(FR!$G$4:$G$500,MATCH(D15,FR!$A$4:$A$500,0)) -> S6
... A25: UC-22 | B25: Đối soát và xử lý giao dịch lỗi | C25: Finance | D25: FR-PAY-03 | E25: FR-PAY-04 | F25: Có giao dịch từ cổng thanh toán. | G25: 1. Hệ thống đối soát tự động callback với đơn. 2. Giao dịch lệch được liệt kê. 3. Finance xử lý (khớp thủ công / từ chối). | H25: A1. Giao dịch đã thu tiền nhưng chưa cấp quyền → cấp quyền thủ công. | I25: Đơn và quyền khớp với tiền thực thu. | J25: =INDEX(FR!$F$4:$F$500,MATCH(D25,FR!$A$4:$A$500,0)) -> Must | K25: =INDEX(FR!$G$4:$G$500,MATCH(D25,FR!$A$4:$A$500,0)) -> S4

Sheet Sprint
A1: KẾ HOẠCH 8 SPRINT (1 TUẦN / SPRINT, ~2 THÁNG)
A2: Chưa gán người. Man-day tự cộng từ sheet FR theo cột Sprint. Đỏ = vượt năng lực.
A3: Sprint | B3: Bắt đầu | C3: Kết thúc | D3: Mục tiêu sprint | E3: Kết quả demo cuối sprint | F3: BA | G3: BE | H3: FE | I3: AI | J3: QA | K3: Dev kế hoạch | L3: Dev năng lực | M3: % Dev | N3: Lead (BA+QA) | O3: Lead năng lực | P3: % Lead | Q3: Cảnh báo | R3: Số FR
A4: S1 | B4: ='Tổng quan'!$C$18+7*0 -> 46300 | C4: =B4+4 -> 46304 | D4: Nền móng & chốt kiến trúc | E4: Repo + CI/CD chạy; CSDL v1; design system; đăng ký/đăng nhập; khung RBAC; báo cáo đánh giá provider AI (chất lượng/giá) và chốt kiến trúc adapter. | F4: =SUMIFS(FR!$H$4:$H$500,FR!$G$4:$G$500,$A4) -> 3.5 | G4: =SUMIFS(FR!$I$4:$I$500,FR!$G$4:$G$500,$A4) -> 6 | H4: =SUMIFS(FR!$J$4:$J$500,FR!$G$4:$G$500,$A4) -> 3.75 | I4: =SUMIFS(FR!$K$4:$K$500,FR!$G$4:$G$500,$A4) -> 3.5 | J4: =SUMIFS(FR!$L$4:$L$500,FR!$G$4:$G$500,$A4) -> 1.5 | K4: =SUM(G4:I4) -> 13.25 | L4: ='Tổng quan'!$C$25 -> 13.5 | M4: =IF(L4=0,0,K4/L4) -> 0.98148148 | N4: =F4+J4 -> 5 | O4: ='Tổng quan'!$C$26 -> 4.25 | P4: =IF(O4=0,0,N4/O4) -> 1.1764706 | Q4: =IF(M4>1,"Dev vượt năng lực","")&IF(AND(M4>1,P4>1)," · ","")&IF(P4>1,"Lead quá tải (BA+QA)","") -> Lead quá tải (BA+QA) | R4: =COUNTIF(FR!$G$4:$G$500,$A4) -> 7
A5: S2 | B5: ='Tổng quan'!$C$18+7*1 -> 46307 | C5: =B5+4 -> 46311 | D5: Catalog, media & lõi pipeline AI | E5: Admin tạo phim/tập, upload video, transcode HLS xem được; quản lý user; pipeline job bất đồng bộ chạy được job mẫu. | F5: =SUMIFS(FR!$H$4:$H$500,FR!$G$4:$G$500,$A5) -> 2.25 | G5: =SUMIFS(FR!$I$4:$I$500,FR!$G$4:$G$500,$A5) -> 7.75 | H5: =SUMIFS(FR!$J$4:$J$500,FR!$G$4:$G$500,$A5) -> 4.25 | I5: =SUMIFS(FR!$K$4:$K$500,FR!$G$4:$G$500,$A5) -> 1.5 | J5: =SUMIFS(FR!$L$4:$L$500,FR!$G$4:$G$500,$A5) -> 2 | K5: =SUM(G5:I5) -> 13.5 | L5: ='Tổng quan'!$C$25 -> 13.5 | M5: =IF(L5=0,0,K5/L5) -> 1 | N5: =F5+J5 -> 4.25 | O5: ='Tổng quan'!$C$26 -> 4.25 | P5: =IF(O5=0,0,N5/O5) -> 1 | Q5: =IF(M5>1,"Dev vượt năng lực","")&IF(AND(M5>1,P5>1)," · ","")&IF(P5>1,"Lead quá tải (BA+QA)","") | R5: =COUNTIF(FR!$G$4:$G$500,$A5) -> 7
A6: S3 | B6: ='Tổng quan'!$C$18+7*2 -> 46314 | C6: =B6+4 -> 46318 | D6: Storefront & phễu từ social | E6: Trang chủ, chi tiết phim, trình phát HLS; landing theo chiến dịch + ghi UTM/click-id; định giá & vòng đời xuất bản; email giao dịch. | F6: =SUMIFS(FR!$H$4:$H$500,FR!$G$4:$G$500,$A6) -> 2.85 | G6: =SUMIFS(FR!$I$4:$I$500,FR!$G$4:$G$500,$A6) -> 4.5 | H6: =SUMIFS(FR!$J$4:$J$500,FR!$G$4:$G$500,$A6) -> 8.75 | I6: =SUMIFS(FR!$K$4:$K$500,FR!$G$4:$G$500,$A6) -> 0 | J6: =SUMIFS(FR!$L$4:$L$500,FR!$G$4:$G$500,$A6) -> 2.5 | K6: =SUM(G6:I6) -> 13.25 | L6: ='Tổng quan'!$C$25 -> 13.5 | M6: =IF(L6=0,0,K6/L6) -> 0.98148148 | N6: =F6+J6 -> 5.35 | O6: ='Tổng quan'!$C$26 -> 4.25 | P6: =IF(O6=0,0,N6/O6) -> 1.2588235 | Q6: =IF(M6>1,"Dev vượt năng lực","")&IF(AND(M6>1,P6>1)," · ","")&IF(P6>1,"Lead quá tải (BA+QA)","") -> Lead quá tải (BA+QA) | R6: =COUNTIF(FR!$G$4:$G$500,$A6) -> 8
A7: S4 | B7: ='Tổng quan'!$C$18+7*3 -> 46321 | C7: =B7+4 -> 46325 | D7: Thanh toán mua lẻ & quyền xem | E7: Mua lẻ bằng cổng nội địa end-to-end, webhook idempotent, cấp entitlement, signed URL; tìm kiếm; trang pháp lý. | F7: =SUMIFS(FR!$H$4:$H$500,FR!$G$4:$G$500,$A7) -> 2.5 | G7: =SUMIFS(FR!$I$4:$I$500,FR!$G$4:$G$500,$A7) -> 9.5 | H7: =SUMIFS(FR!$J$4:$J$500,FR!$G$4:$G$500,$A7) -> 3.5 | I7: =SUMIFS(FR!$K$4:$K$500,FR!$G$4:$G$500,$A7) -> 0 | J7: =SUMIFS(FR!$L$4:$L$500,FR!$G$4:$G$500,$A7) -> 3 | K7: =SUM(G7:I7) -> 13 | L7: ='Tổng quan'!$C$25 -> 13.5 | M7: =IF(L7=0,0,K7/L7) -> 0.96296296 | N7: =F7+J7 -> 5.5 | O7: ='Tổng quan'!$C$26 -> 4.25 | P7: =IF(O7=0,0,N7/O7) -> 1.2941176 | Q7: =IF(M7>1,"Dev vượt năng lực","")&IF(AND(M7>1,P7>1)," · ","")&IF(P7>1,"Lead quá tải (BA+QA)","") -> Lead quá tải (BA+QA) | R7: =COUNTIF(FR!$G$4:$G$500,$A7) -> 8
A8: S5 | B8: ='Tổng quan'!$C$18+7*4 -> 46328 | C8: =B8+4 -> 46332 | D8: AI Studio 1: ý tưởng → storyboard → keyframe | E8: Creator nhập brief → sinh kịch bản → storyboard → keyframe; theo dõi job realtime; Pixel/CAPI; ghi nhận sự kiện xem. | F8: =SUMIFS(FR!$H$4:$H$500,FR!$G$4:$G$500,$A8) -> 1.45 | G8: =SUMIFS(FR!$I$4:$I$500,FR!$G$4:$G$500,$A8) -> 4 | H8: =SUMIFS(FR!$J$4:$J$500,FR!$G$4:$G$500,$A8) -> 4.75 | I8: =SUMIFS(FR!$K$4:$K$500,FR!$G$4:$G$500,$A8) -> 4.5 | J8: =SUMIFS(FR!$L$4:$L$500,FR!$G$4:$G$500,$A8) -> 1.6 | K8: =SUM(G8:I8) -> 13.25 | L8: ='Tổng quan'!$C$25 -> 13.5 | M8: =IF(L8=0,0,K8/L8) -> 0.98148148 | N8: =F8+J8 -> 3.05 | O8: ='Tổng quan'!$C$26 -> 4.25 | P8: =IF(O8=0,0,N8/O8) -> 0.71764706 | Q8: =IF(M8>1,"Dev vượt năng lực","")&IF(AND(M8>1,P8>1)," · ","")&IF(P8>1,"Lead quá tải (BA+QA)","") | R8: =COUNTIF(FR!$G$4:$G$500,$A8) -> 7
A9: S6 | B9: ='Tổng quan'!$C$18+7*5 -> 46335 | C9: =B9+4 -> 46339 | D9: AI Studio 2: clip, giọng, dựng phim | E9: Sinh clip từng cảnh, nhân vật nhất quán, TTS, tự ghép thành phim MP4/HLS; hạn mức & chi phí AI. | F9: =SUMIFS(FR!$H$4:$H$500,FR!$G$4:$G$500,$A9) -> 1.75 | G9: =SUMIFS(FR!$I$4:$I$500,FR!$G$4:$G$500,$A9) -> 3.75 | H9: =SUMIFS(FR!$J$4:$J$500,FR!$G$4:$G$500,$A9) -> 2.75 | I9: =SUMIFS(FR!$K$4:$K$500,FR!$G$4:$G$500,$A9) -> 7.25 | J9: =SUMIFS(FR!$L$4:$L$500,FR!$G$4:$G$500,$A9) -> 1.6 | K9: =SUM(G9:I9) -> 13.75 | L9: ='Tổng quan'!$C$25 -> 13.5 | M9: =IF(L9=0,0,K9/L9) -> 1.0185185 | N9: =F9+J9 -> 3.35 | O9: ='Tổng quan'!$C$26 -> 4.25 | P9: =IF(O9=0,0,N9/O9) -> 0.78823529 | Q9: =IF(M9>1,"Dev vượt năng lực","")&IF(AND(M9>1,P9>1)," · ","")&IF(P9>1,"Lead quá tải (BA+QA)","") -> Dev vượt năng lực | R9: =COUNTIF(FR!$G$4:$G$500,$A9) -> 5
A10: S7 | B10: ='Tổng quan'!$C$18+7*6 -> 46342 | C10: =B10+4 -> 46346 | D10: Duyệt & xuất bản, gói thuê bao, dashboard | E10: Kiểm duyệt AI, regenerate/phiên bản, duyệt & xuất bản vào Catalog; gói thuê bao; dashboard & phễu chuyển đổi. | F10: =SUMIFS(FR!$H$4:$H$500,FR!$G$4:$G$500,$A10) -> 2.5 | G10: =SUMIFS(FR!$I$4:$I$500,FR!$G$4:$G$500,$A10) -> 5.5 | H10: =SUMIFS(FR!$J$4:$J$500,FR!$G$4:$G$500,$A10) -> 6 | I10: =SUMIFS(FR!$K$4:$K$500,FR!$G$4:$G$500,$A10) -> 1.5 | J10: =SUMIFS(FR!$L$4:$L$500,FR!$G$4:$G$500,$A10) -> 1.8 | K10: =SUM(G10:I10) -> 13 | L10: ='Tổng quan'!$C$25 -> 13.5 | M10: =IF(L10=0,0,K10/L10) -> 0.96296296 | N10: =F10+J10 -> 4.3 | O10: ='Tổng quan'!$C$26 -> 4.25 | P10: =IF(O10=0,0,N10/O10) -> 1.0117647 | Q10: =IF(M10>1,"Dev vượt năng lực","")&IF(AND(M10>1,P10>1)," · ","")&IF(P10>1,"Lead quá tải (BA+QA)","") -> Lead quá tải (BA+QA) | R10: =COUNTIF(FR!$G$4:$G$500,$A10) -> 6
A11: S8 | B11: ='Tổng quan'!$C$18+7*7 -> 46349 | C11: =B11+4 -> 46353 | D11: Audit log, hardening, UAT & bàn giao | E11: Bảo mật, load test, UAT cùng khách, sửa lỗi, tài liệu, bàn giao; dự phòng cho bug từ các sprint trước. | F11: =SUMIFS(FR!$H$4:$H$500,FR!$G$4:$G$500,$A11) -> 3.75 | G11: =SUMIFS(FR!$I$4:$I$500,FR!$G$4:$G$500,$A11) -> 4.5 | H11: =SUMIFS(FR!$J$4:$J$500,FR!$G$4:$G$500,$A11) -> 2.75 | I11: =SUMIFS(FR!$K$4:$K$500,FR!$G$4:$G$500,$A11) -> 0.75 | J11: =SUMIFS(FR!$L$4:$L$500,FR!$G$4:$G$500,$A11) -> 3.4 | K11: =SUM(G11:I11) -> 8 | L11: ='Tổng quan'!$C$25 -> 13.5 | M11: =IF(L11=0,0,K11/L11) -> 0.59259259 | N11: =F11+J11 -> 7.15 | O11: ='Tổng quan'!$C$26 -> 4.25 | P11: =IF(O11=0,0,N11/O11) -> 1.6823529 | Q11: =IF(M11>1,"Dev vượt năng lực","")&IF(AND(M11>1,P11>1)," · ","")&IF(P11>1,"Lead quá tải (BA+QA)","") -> Lead quá tải (BA+QA) | R11: =COUNTIF(FR!$G$4:$G$500,$A11) -> 5
A12: Tổng 8 sprint | F12: =SUM(F4:F11) -> 20.55 | G12: =SUM(G4:G11) -> 45.5 | H12: =SUM(H4:H11) -> 36.5 | I12: =SUM(I4:I11) -> 19 | J12: =SUM(J4:J11) -> 17.4 | K12: =SUM(K4:K11) -> 101 | L12: =SUM(L4:L11) -> 108 | M12: =IF(L12=0,0,K12/L12) -> 0.93518519 | N12: =SUM(N4:N11) -> 37.95 | O12: =SUM(O4:O11) -> 34 | P12: =IF(O12=0,0,N12/O12) -> 1.1161765 | R12: =SUM(R4:R11) -> 53
A13: Backlog (Phase 2) | F13: =SUMIFS(FR!$H$4:$H$500,FR!$G$4:$G$500,"Backlog") -> 11.45 | G13: =SUMIFS(FR!$I$4:$I$500,FR!$G$4:$G$500,"Backlog") -> 28.85 | H13: =SUMIFS(FR!$J$4:$J$500,FR!$G$4:$G$500,"Backlog") -> 30.25 | I13: =SUMIFS(FR!$K$4:$K$500,FR!$G$4:$G$500,"Backlog") -> 4.75 | J13: =SUMIFS(FR!$L$4:$L$500,FR!$G$4:$G$500,"Backlog") -> 10.6 | K13: =SUM(G13:I13) -> 63.85 | N13: =F13+J13 -> 22.05 | R13: =COUNTIF(FR!$G$4:$G$500,"Backlog") -> 42
A15: Ghi chú: S8 cố ý để trống ~40% năng lực dev làm bộ đệm sửa lỗi/UAT. Ràng buộc phụ thuộc chính: S1 → S2 (pipeline) → S5–S6 (AI Studio) → S7 (xuất bản); S3–S4 (storefront → thanh toán) chạy song song với pipeline AI.

Sheet Effort
A1: TỔNG HỢP EFFORT THEO MODULE & ƯU TIÊN
A2: Tất cả số liệu là công thức từ sheet FR. 'Trong kế hoạch' = FR có sprint S1–S8.
A3: Module | B3: Số FR | C3: Must | D3: Should | E3: Could | F3: FR trong kế hoạch | G3: FR Backlog | H3: BA | I3: BE | J3: FE | K3: AI | L3: QA | M3: Man-day trong kế hoạch | N3: Man-day Backlog
A4: SYS · Nền tảng & hạ tầng | B4: =COUNTIF(FR!$B$4:$B$500,$A4) -> 11 | C4: =COUNTIFS(FR!$B$4:$B$500,$A4,FR!$F$4:$F$500,"Must") -> 8 | D4: =COUNTIFS(FR!$B$4:$B$500,$A4,FR!$F$4:$F$500,"Should") -> 2 | E4: =COUNTIFS(FR!$B$4:$B$500,$A4,FR!$F$4:$F$500,"Could") -> 1 | F4: =COUNTIFS(FR!$B$4:$B$500,$A4,FR!$G$4:$G$500,"<>Backlog") -> 8 | G4: =COUNTIFS(FR!$B$4:$B$500,$A4,FR!$G$4:$G$500,"Backlog") -> 3 | H4: =SUMIFS(FR!$H$4:$H$500,FR!$B$4:$B$500,$A4,FR!$G$4:$G$500,"<>Backlog") -> 5.25 | I4: =SUMIFS(FR!$I$4:$I$500,FR!$B$4:$B$500,$A4,FR!$G$4:$G$500,"<>Backlog") -> 7 | J4: =SUMIFS(FR!$J$4:$J$500,FR!$B$4:$B$500,$A4,FR!$G$4:$G$500,"<>Backlog") -> 5.25 | K4: =SUMIFS(FR!$K$4:$K$500,FR!$B$4:$B$500,$A4,FR!$G$4:$G$500,"<>Backlog") -> 1.25 | L4: =SUMIFS(FR!$L$4:$L$500,FR!$B$4:$B$500,$A4,FR!$G$4:$G$500,"<>Backlog") -> 4 | M4: =SUM(H4:L4) -> 22.75 | N4: =SUMIFS(FR!$M$4:$M$500,FR!$B$4:$B$500,$A4,FR!$G$4:$G$500,"Backlog") -> 5.55
A5: AUTH · Tài khoản & xác thực | B5: =COUNTIF(FR!$B$4:$B$500,$A5) -> 7 | C5: =COUNTIFS(FR!$B$4:$B$500,$A5,FR!$F$4:$F$500,"Must") -> 3 | D5: =COUNTIFS(FR!$B$4:$B$500,$A5,FR!$F$4:$F$500,"Should") -> 2 | E5: =COUNTIFS(FR!$B$4:$B$500,$A5,FR!$F$4:$F$500,"Could") -> 2 | F5: =COUNTIFS(FR!$B$4:$B$500,$A5,FR!$G$4:$G$500,"<>Backlog") -> 3 | G5: =COUNTIFS(FR!$B$4:$B$500,$A5,FR!$G$4:$G$500,"Backlog") -> 4 | H5: =SUMIFS(FR!$H$4:$H$500,FR!$B$4:$B$500,$A5,FR!$G$4:$G$500,"<>Backlog") -> 0.75 | I5: =SUMIFS(FR!$I$4:$I$500,FR!$B$4:$B$500,$A5,FR!$G$4:$G$500,"<>Backlog") -> 2 | J5: =SUMIFS(FR!$J$4:$J$500,FR!$B$4:$B$500,$A5,FR!$G$4:$G$500,"<>Backlog") -> 1.25 | K5: =SUMIFS(FR!$K$4:$K$500,FR!$B$4:$B$500,$A5,FR!$G$4:$G$500,"<>Backlog") -> 0 | L5: =SUMIFS(FR!$L$4:$L$500,FR!$B$4:$B$500,$A5,FR!$G$4:$G$500,"<>Backlog") -> 0.6 | M5: =SUM(H5:L5) -> 4.6 | N5: =SUMIFS(FR!$M$4:$M$500,FR!$B$4:$B$500,$A5,FR!$G$4:$G$500,"Backlog") -> 7.2
A6: ADM · Admin & phân quyền | B6: =COUNTIF(FR!$B$4:$B$500,$A6) -> 8 | C6: =COUNTIFS(FR!$B$4:$B$500,$A6,FR!$F$4:$F$500,"Must") -> 3 | D6: =COUNTIFS(FR!$B$4:$B$500,$A6,FR!$F$4:$F$500,"Should") -> 4 | E6: =COUNTIFS(FR!$B$4:$B$500,$A6,FR!$F$4:$F$500,"Could") -> 1 | F6: =COUNTIFS(FR!$B$4:$B$500,$A6,FR!$G$4:$G$500,"<>Backlog") -> 4 | G6: =COUNTIFS(FR!$B$4:$B$500,$A6,FR!$G$4:$G$500,"Backlog") -> 4 | H6: =SUMIFS(FR!$H$4:$H$500,FR!$B$4:$B$500,$A6,FR!$G$4:$G$500,"<>Backlog") -> 2 | I6: =SUMIFS(FR!$I$4:$I$500,FR!$B$4:$B$500,$A6,FR!$G$4:$G$500,"<>Backlog") -> 3.75 | J6: =SUMIFS(FR!$J$4:$J$500,FR!$B$4:$B$500,$A6,FR!$G$4:$G$500,"<>Backlog") -> 3.25 | K6: =SUMIFS(FR!$K$4:$K$500,FR!$B$4:$B$500,$A6,FR!$G$4:$G$500,"<>Backlog") -> 0 | L6: =SUMIFS(FR!$L$4:$L$500,FR!$B$4:$B$500,$A6,FR!$G$4:$G$500,"<>Backlog") -> 1.2 | M6: =SUM(H6:L6) -> 10.2 | N6: =SUMIFS(FR!$M$4:$M$500,FR!$B$4:$B$500,$A6,FR!$G$4:$G$500,"Backlog") -> 8.75
A7: CAT · Quản lý danh mục phim | B7: =COUNTIF(FR!$B$4:$B$500,$A7) -> 7 | C7: =COUNTIFS(FR!$B$4:$B$500,$A7,FR!$F$4:$F$500,"Must") -> 4 | D7: =COUNTIFS(FR!$B$4:$B$500,$A7,FR!$F$4:$F$500,"Should") -> 1 | E7: =COUNTIFS(FR!$B$4:$B$500,$A7,FR!$F$4:$F$500,"Could") -> 2 | F7: =COUNTIFS(FR!$B$4:$B$500,$A7,FR!$G$4:$G$500,"<>Backlog") -> 4 | G7: =COUNTIFS(FR!$B$4:$B$500,$A7,FR!$G$4:$G$500,"Backlog") -> 3 | H7: =SUMIFS(FR!$H$4:$H$500,FR!$B$4:$B$500,$A7,FR!$G$4:$G$500,"<>Backlog") -> 1.75 | I7: =SUMIFS(FR!$I$4:$I$500,FR!$B$4:$B$500,$A7,FR!$G$4:$G$500,"<>Backlog") -> 3.25 | J7: =SUMIFS(FR!$J$4:$J$500,FR!$B$4:$B$500,$A7,FR!$G$4:$G$500,"<>Backlog") -> 3.5 | K7: =SUMIFS(FR!$K$4:$K$500,FR!$B$4:$B$500,$A7,FR!$G$4:$G$500,"<>Backlog") -> 0 | L7: =SUMIFS(FR!$L$4:$L$500,FR!$B$4:$B$500,$A7,FR!$G$4:$G$500,"<>Backlog") -> 1.2 | M7: =SUM(H7:L7) -> 9.7 | N7: =SUMIFS(FR!$M$4:$M$500,FR!$B$4:$B$500,$A7,FR!$G$4:$G$500,"Backlog") -> 6.3
A8: MED · Media & streaming | B8: =COUNTIF(FR!$B$4:$B$500,$A8) -> 5 | C8: =COUNTIFS(FR!$B$4:$B$500,$A8,FR!$F$4:$F$500,"Must") -> 3 | D8: =COUNTIFS(FR!$B$4:$B$500,$A8,FR!$F$4:$F$500,"Should") -> 2 | E8: =COUNTIFS(FR!$B$4:$B$500,$A8,FR!$F$4:$F$500,"Could") -> 0 | F8: =COUNTIFS(FR!$B$4:$B$500,$A8,FR!$G$4:$G$500,"<>Backlog") -> 3 | G8: =COUNTIFS(FR!$B$4:$B$500,$A8,FR!$G$4:$G$500,"Backlog") -> 2 | H8: =SUMIFS(FR!$H$4:$H$500,FR!$B$4:$B$500,$A8,FR!$G$4:$G$500,"<>Backlog") -> 0.75 | I8: =SUMIFS(FR!$I$4:$I$500,FR!$B$4:$B$500,$A8,FR!$G$4:$G$500,"<>Backlog") -> 5 | J8: =SUMIFS(FR!$J$4:$J$500,FR!$B$4:$B$500,$A8,FR!$G$4:$G$500,"<>Backlog") -> 1 | K8: =SUMIFS(FR!$K$4:$K$500,FR!$B$4:$B$500,$A8,FR!$G$4:$G$500,"<>Backlog") -> 0 | L8: =SUMIFS(FR!$L$4:$L$500,FR!$B$4:$B$500,$A8,FR!$G$4:$G$500,"<>Backlog") -> 1 | M8: =SUM(H8:L8) -> 7.75 | N8: =SUMIFS(FR!$M$4:$M$500,FR!$B$4:$B$500,$A8,FR!$G$4:$G$500,"Backlog") -> 3.15
A9: PLY · Storefront & trình phát | B9: =COUNTIF(FR!$B$4:$B$500,$A9) -> 9 | C9: =COUNTIFS(FR!$B$4:$B$500,$A9,FR!$F$4:$F$500,"Must") -> 5 | D9: =COUNTIFS(FR!$B$4:$B$500,$A9,FR!$F$4:$F$500,"Should") -> 2 | E9: =COUNTIFS(FR!$B$4:$B$500,$A9,FR!$F$4:$F$500,"Could") -> 2 | F9: =COUNTIFS(FR!$B$4:$B$500,$A9,FR!$G$4:$G$500,"<>Backlog") -> 5 | G9: =COUNTIFS(FR!$B$4:$B$500,$A9,FR!$G$4:$G$500,"Backlog") -> 4 | H9: =SUMIFS(FR!$H$4:$H$500,FR!$B$4:$B$500,$A9,FR!$G$4:$G$500,"<>Backlog") -> 1.75 | I9: =SUMIFS(FR!$I$4:$I$500,FR!$B$4:$B$500,$A9,FR!$G$4:$G$500,"<>Backlog") -> 2.75 | J9: =SUMIFS(FR!$J$4:$J$500,FR!$B$4:$B$500,$A9,FR!$G$4:$G$500,"<>Backlog") -> 6.75 | K9: =SUMIFS(FR!$K$4:$K$500,FR!$B$4:$B$500,$A9,FR!$G$4:$G$500,"<>Backlog") -> 0 | L9: =SUMIFS(FR!$L$4:$L$500,FR!$B$4:$B$500,$A9,FR!$G$4:$G$500,"<>Backlog") -> 1.8 | M9: =SUM(H9:L9) -> 13.05 | N9: =SUMIFS(FR!$M$4:$M$500,FR!$B$4:$B$500,$A9,FR!$G$4:$G$500,"Backlog") -> 6.8
A10: SOC · Social funnel & marketing | B10: =COUNTIF(FR!$B$4:$B$500,$A10) -> 9 | C10: =COUNTIFS(FR!$B$4:$B$500,$A10,FR!$F$4:$F$500,"Must") -> 3 | D10: =COUNTIFS(FR!$B$4:$B$500,$A10,FR!$F$4:$F$500,"Should") -> 4 | E10: =COUNTIFS(FR!$B$4:$B$500,$A10,FR!$F$4:$F$500,"Could") -> 2 | F10: =COUNTIFS(FR!$B$4:$B$500,$A10,FR!$G$4:$G$500,"<>Backlog") -> 3 | G10: =COUNTIFS(FR!$B$4:$B$500,$A10,FR!$G$4:$G$500,"Backlog") -> 6 | H10: =SUMIFS(FR!$H$4:$H$500,FR!$B$4:$B$500,$A10,FR!$G$4:$G$500,"<>Backlog") -> 1 | I10: =SUMIFS(FR!$I$4:$I$500,FR!$B$4:$B$500,$A10,FR!$G$4:$G$500,"<>Backlog") -> 2.25 | J10: =SUMIFS(FR!$J$4:$J$500,FR!$B$4:$B$500,$A10,FR!$G$4:$G$500,"<>Backlog") -> 2 | K10: =SUMIFS(FR!$K$4:$K$500,FR!$B$4:$B$500,$A10,FR!$G$4:$G$500,"<>Backlog") -> 0 | L10: =SUMIFS(FR!$L$4:$L$500,FR!$B$4:$B$500,$A10,FR!$G$4:$G$500,"<>Backlog") -> 1 | M10: =SUM(H10:L10) -> 6.25 | N10: =SUMIFS(FR!$M$4:$M$500,FR!$B$4:$B$500,$A10,FR!$G$4:$G$500,"Backlog") -> 13.9
A11: PAY · Thanh toán & gói | B11: =COUNTIF(FR!$B$4:$B$500,$A11) -> 10 | C11: =COUNTIFS(FR!$B$4:$B$500,$A11,FR!$F$4:$F$500,"Must") -> 5 | D11: =COUNTIFS(FR!$B$4:$B$500,$A11,FR!$F$4:$F$500,"Should") -> 4 | E11: =COUNTIFS(FR!$B$4:$B$500,$A11,FR!$F$4:$F$500,"Could") -> 1 | F11: =COUNTIFS(FR!$B$4:$B$500,$A11,FR!$G$4:$G$500,"<>Backlog") -> 5 | G11: =COUNTIFS(FR!$B$4:$B$500,$A11,FR!$G$4:$G$500,"Backlog") -> 5 | H11: =SUMIFS(FR!$H$4:$H$500,FR!$B$4:$B$500,$A11,FR!$G$4:$G$500,"<>Backlog") -> 1.75 | I11: =SUMIFS(FR!$I$4:$I$500,FR!$B$4:$B$500,$A11,FR!$G$4:$G$500,"<>Backlog") -> 7.5 | J11: =SUMIFS(FR!$J$4:$J$500,FR!$B$4:$B$500,$A11,FR!$G$4:$G$500,"<>Backlog") -> 2.5 | K11: =SUMIFS(FR!$K$4:$K$500,FR!$B$4:$B$500,$A11,FR!$G$4:$G$500,"<>Backlog") -> 0 | L11: =SUMIFS(FR!$L$4:$L$500,FR!$B$4:$B$500,$A11,FR!$G$4:$G$500,"<>Backlog") -> 2.4 | M11: =SUM(H11:L11) -> 14.15 | N11: =SUMIFS(FR!$M$4:$M$500,FR!$B$4:$B$500,$A11,FR!$G$4:$G$500,"Backlog") -> 11
A12: AIV · AI Film Studio (pipeline) | B12: =COUNTIF(FR!$B$4:$B$500,$A12) -> 21 | C12: =COUNTIFS(FR!$B$4:$B$500,$A12,FR!$F$4:$F$500,"Must") -> 15 | D12: =COUNTIFS(FR!$B$4:$B$500,$A12,FR!$F$4:$F$500,"Should") -> 4 | E12: =COUNTIFS(FR!$B$4:$B$500,$A12,FR!$F$4:$F$500,"Could") -> 2 | F12: =COUNTIFS(FR!$B$4:$B$500,$A12,FR!$G$4:$G$500,"<>Backlog") -> 15 | G12: =COUNTIFS(FR!$B$4:$B$500,$A12,FR!$G$4:$G$500,"Backlog") -> 6 | H12: =SUMIFS(FR!$H$4:$H$500,FR!$B$4:$B$500,$A12,FR!$G$4:$G$500,"<>Backlog") -> 5.1 | I12: =SUMIFS(FR!$I$4:$I$500,FR!$B$4:$B$500,$A12,FR!$G$4:$G$500,"<>Backlog") -> 9.25 | J12: =SUMIFS(FR!$J$4:$J$500,FR!$B$4:$B$500,$A12,FR!$G$4:$G$500,"<>Backlog") -> 9 | K12: =SUMIFS(FR!$K$4:$K$500,FR!$B$4:$B$500,$A12,FR!$G$4:$G$500,"<>Backlog") -> 17.75 | L12: =SUMIFS(FR!$L$4:$L$500,FR!$B$4:$B$500,$A12,FR!$G$4:$G$500,"<>Backlog") -> 3.7 | M12: =SUM(H12:L12) -> 44.8 | N12: =SUMIFS(FR!$M$4:$M$500,FR!$B$4:$B$500,$A12,FR!$G$4:$G$500,"Backlog") -> 17.5
A13: NOT · Thông báo | B13: =COUNTIF(FR!$B$4:$B$500,$A13) -> 4 | C13: =COUNTIFS(FR!$B$4:$B$500,$A13,FR!$F$4:$F$500,"Must") -> 1 | D13: =COUNTIFS(FR!$B$4:$B$500,$A13,FR!$F$4:$F$500,"Should") -> 2 | E13: =COUNTIFS(FR!$B$4:$B$500,$A13,FR!$F$4:$F$500,"Could") -> 1 | F13: =COUNTIFS(FR!$B$4:$B$500,$A13,FR!$G$4:$G$500,"<>Backlog") -> 1 | G13: =COUNTIFS(FR!$B$4:$B$500,$A13,FR!$G$4:$G$500,"Backlog") -> 3 | H13: =SUMIFS(FR!$H$4:$H$500,FR!$B$4:$B$500,$A13,FR!$G$4:$G$500,"<>Backlog") -> 0.1 | I13: =SUMIFS(FR!$I$4:$I$500,FR!$B$4:$B$500,$A13,FR!$G$4:$G$500,"<>Backlog") -> 0.75 | J13: =SUMIFS(FR!$J$4:$J$500,FR!$B$4:$B$500,$A13,FR!$G$4:$G$500,"<>Backlog") -> 0.25 | K13: =SUMIFS(FR!$K$4:$K$500,FR!$B$4:$B$500,$A13,FR!$G$4:$G$500,"<>Backlog") -> 0 | L13: =SUMIFS(FR!$L$4:$L$500,FR!$B$4:$B$500,$A13,FR!$G$4:$G$500,"<>Backlog") -> 0.1 | M13: =SUM(H13:L13) -> 1.2 | N13: =SUMIFS(FR!$M$4:$M$500,FR!$B$4:$B$500,$A13,FR!$G$4:$G$500,"Backlog") -> 2.85
A14: ANA · Analytics & báo cáo | B14: =COUNTIF(FR!$B$4:$B$500,$A14) -> 4 | C14: =COUNTIFS(FR!$B$4:$B$500,$A14,FR!$F$4:$F$500,"Must") -> 2 | D14: =COUNTIFS(FR!$B$4:$B$500,$A14,FR!$F$4:$F$500,"Should") -> 1 | E14: =COUNTIFS(FR!$B$4:$B$500,$A14,FR!$F$4:$F$500,"Could") -> 1 | F14: =COUNTIFS(FR!$B$4:$B$500,$A14,FR!$G$4:$G$500,"<>Backlog") -> 2 | G14: =COUNTIFS(FR!$B$4:$B$500,$A14,FR!$G$4:$G$500,"Backlog") -> 2 | H14: =SUMIFS(FR!$H$4:$H$500,FR!$B$4:$B$500,$A14,FR!$G$4:$G$500,"<>Backlog") -> 0.35 | I14: =SUMIFS(FR!$I$4:$I$500,FR!$B$4:$B$500,$A14,FR!$G$4:$G$500,"<>Backlog") -> 2 | J14: =SUMIFS(FR!$J$4:$J$500,FR!$B$4:$B$500,$A14,FR!$G$4:$G$500,"<>Backlog") -> 1.75 | K14: =SUMIFS(FR!$K$4:$K$500,FR!$B$4:$B$500,$A14,FR!$G$4:$G$500,"<>Backlog") -> 0 | L14: =SUMIFS(FR!$L$4:$L$500,FR!$B$4:$B$500,$A14,FR!$G$4:$G$500,"<>Backlog") -> 0.4 | M14: =SUM(H14:L14) -> 4.5 | N14: =SUMIFS(FR!$M$4:$M$500,FR!$B$4:$B$500,$A14,FR!$G$4:$G$500,"Backlog") -> 2.9
A15: TỔNG | B15: =SUM(B4:B14) -> 95 | C15: =SUM(C4:C14) -> 52 | D15: =SUM(D4:D14) -> 28 | E15: =SUM(E4:E14) -> 15 | F15: =SUM(F4:F14) -> 53 | G15: =SUM(G4:G14) -> 42 | H15: =SUM(H4:H14) -> 20.55 | I15: =SUM(I4:I14) -> 45.5 | ... N15: =SUM(N4:N14) -> 85.9
A17: ƯỚC TÍNH CHI PHÍ NHÂN SỰ (chưa gồm API AI & hạ tầng)
A18: Man-day trong kế hoạch | B18: =M15 -> 138.95
A19: Đơn giá / man-day (nhập ở 'Tổng quan') | B19: =IF('Tổng quan'!$C$24="","",'Tổng quan'!$C$24)
A20: Chi phí nhân sự MVP (VND) | B20: =IF(B19="","Chưa nhập đơn giá",B18*B19) -> Chưa nhập đơn giá
A21: Chi phí Backlog / Phase 2 (VND) | B21: =IF(B19="","Chưa nhập đơn giá",N15*B19) -> Chưa nhập đơn giá

Sheet Rủi ro-Câu hỏi
A1: CÂU HỎI CẦN CHỐT VỚI KHÁCH & RỦI RO
A3: # | B3: Câu hỏi cho khách hàng | C3: Vì sao quan trọng / ảnh hưởng | D3: Giả định hiện tại | E3: Câu trả lời của khách | F3: Ảnh hưởng FR
A4: 1 | B4: Ai là người tạo phim: đội studio nội bộ hay khách cuối tự tạo (UGC)? | C4: UGC kéo theo kiểm duyệt, chi phí AI, ví credit, chống lạm dụng — tăng ~10–15 man-day và rủi ro pháp lý. | D4: Chỉ Creator nội bộ; UGC ở Phase 2. | F4: FR-AIV-21, FR-PAY-10
A5: 2 | B5: Mục tiêu chất lượng & thời lượng: phim 2–30 phút hay tới 60 phút? Phong cách (hoạt hình/realistic)? Có cần nhân vật nhất quán? | C5: Quyết định provider AI, chi phí/phút và độ khó ghép cảnh. Nhân vật nhất quán là phần khó nhất. | D5: Ghép từ cảnh 5–10s; 2–30 phút là chính; nhất quán nhân vật ở mức tham chiếu ảnh. | F5: FR-AIV-06, FR-AIV-08
A6: 3 | B6: Ngân sách API AI mỗi phút phim là bao nhiêu? Ai trả chi phí API? | C6: Chi phí sinh video AI lớn và thay đổi theo provider; ảnh hưởng giá bán & mô hình credit. | D6: Ngoài estimate; có hạn mức theo dự án. | F6: FR-AIV-16
A7: 4 | B7: Nội dung phim là thể loại nào? Có yếu tố 18+, người thật, thương hiệu, bản quyền? | C7: Chính sách nền tảng TikTok/FB và luật về deepfake/nhãn AI; ảnh hưởng kiểm duyệt. | D7: Không 18+, không dùng hình ảnh người thật; có nhãn AI. | F7: FR-AIV-18, FR-AIV-19, FR-SYS-04
A8: 5 | B8: Mô hình bán: mua lẻ theo phim hay theo tập? Giá thuê (xem có hạn) hay sở hữu? Gói tháng/năm gồm những gì? | C8: Ảnh hưởng entitlement, thanh toán, hoàn tiền. | D8: Mua lẻ vĩnh viễn + gói tháng/năm xem không giới hạn. | F8: FR-CAT-05, FR-PAY-04, FR-PAY-05
A9: 6 | B9: Thanh toán: cổng nào (VNPay/MoMo/PayOS/VietQR/Stripe)? Khách đã có tài khoản merchant chưa? | C9: Đăng ký merchant thường mất 1–3 tuần; là rủi ro tiến độ. | D9: Một cổng nội địa; khách nộp hồ sơ ngay sau họp. | F9: FR-PAY-02, FR-PAY-07
A10: 7 | B10: Có cần đăng tự động lên TikTok/FB không, hay chỉ cần trang đích & tracking? | C10: Cần app review, có thể mất nhiều tuần; ngoài tầm kiểm soát. | D10: Chỉ landing + Pixel/CAPI trong 8 tuần. | F10: FR-SOC-03, FR-SOC-08
A11: 8 | B11: Yêu cầu chống sao chép/tải lậu ở mức nào (signed URL, watermark, DRM thương mại)? | C11: DRM thương mại (Widevine/FairPlay) tốn kém và lâu. | D11: Signed URL + tuỳ chọn watermark, không DRM thương mại. | F11: FR-MED-03
A12: 9 | B12: Lượng người dùng đồng thời kỳ vọng? Cần CDN nào? | C12: Quyết định hạ tầng streaming và chi phí băng thông. | D12: Vài trăm CCU giai đoạn đầu; CDN thuê ngoài. | F12: FR-MED-04, FR-SYS-08
A13: 10 | B13: Hosting: cloud nào, dữ liệu đặt ở đâu? Ngân sách hạ tầng? | C13: Ảnh hưởng thiết kế và chi phí vận hành. | D13: Cloud/VPS + object storage + CDN; khách chọn. | F13: FR-SYS-01
A14: 11 | B14: Ngôn ngữ giao diện & thị trường mục tiêu (chỉ VN hay quốc tế)? | C14: Ảnh hưởng i18n, thanh toán, phụ đề. | D14: Chỉ tiếng Việt, thị trường VN. | F14: FR-SYS-11, FR-CAT-06
A15: 12 | B15: Ai vận hành sau bàn giao (đội nào duyệt phim, kiểm duyệt, chăm sóc khách)? | C15: Định nghĩa vai trò và mức tự động hóa của kiểm duyệt. | D15: Khách có Content Manager + Moderator riêng. | F15: FR-ADM-01, FR-AIV-17
A16: 13 | B16: Thương hiệu, tài liệu nhận diện, nội dung mẫu, phim/trailer cần có khi chạy thử? | C16: Chặn tiến độ FE/nội dung nếu thiếu sớm. | D16: Khách cung cấp brand kit trước Sprint 3. | F16: FR-SYS-03, FR-PLY-01
A18: RỦI RO CHÍNH
A19: # | B19: Rủi ro | C19: Tác động | D19: Biện pháp giảm thiểu | E19: Mức độ | F19: Liên quan
A20: 1 | B20: Chi phí API sinh video vượt dự kiến | C20: Ăn mòn biên lợi nhuận; khó định giá phim | D20: Hạn mức theo dự án, ước tính chi phí trước khi chạy, preview độ phân giải thấp, adapter đa provider | E20: Cao | F20: FR-AIV-16, FR-AIV-01
A21: 2 | B21: Nhân vật/phong cách không nhất quán giữa các cảnh | C21: Phim khó xem, tốn thời gian regenerate | D21: Ảnh tham chiếu + style preset, cho duyệt keyframe trước khi tạo clip, spike đánh giá ở Sprint 1 | E21: Cao | F21: FR-AIV-06, FR-AIV-07
A22: 3 | B22: Thời gian render/độ trễ và rate-limit của provider | C22: Phim 30–60 phút mất nhiều giờ | D22: Job bất đồng bộ, xếp hàng, chạy song song có giới hạn, báo tiến độ | E22: Trung bình | F22: FR-AIV-02, FR-AIV-15
A23: 4 | B23: Bản quyền, deepfake và chính sách nhãn AI của TikTok/Facebook | C23: Bị gỡ nội dung/khóa tài khoản, rủi ro pháp lý | D23: Kiểm duyệt prompt/kết quả, nhãn AI, điều khoản rõ ràng | E23: Cao | F23: FR-AIV-18, FR-AIV-19
A24: 5 | B24: Đăng ký cổng thanh toán và app review social chậm | C24: Trễ tính năng doanh thu | D24: Khách nộp hồ sơ ngay; có phương án chuyển khoản/VietQR tạm | E24: Cao | F24: FR-PAY-02, FR-SOC-08
A25: 6 | B25: Năng lực team hạn chế (3 dev, 1 lead kiêm BA + QA) | C25: S3–S4 và S8 lead quá tải; ít bộ đệm | D25: Dev tự viết test cho tính năng của mình, chốt scope sớm, đưa Should sang Phase 2; cân nhắc QA bán thời gian | E25: Cao | F25: Sheet 'Sprint'
A26: 7 | B26: Scope creep từ khách sau họp | C26: Vỡ kế hoạch 8 tuần | D26: Khóa baseline FR sau họp; thay đổi đi qua change request | E26: Trung bình | F26: —
A27: 8 | B27: Quy mô phim dài làm tăng dung lượng lưu trữ và băng thông | C27: Chi phí hạ tầng | D27: Chọn bitrate hợp lý, lifecycle storage, CDN | E27: Trung bình | F27: FR-MED-02, FR-MED-04
